<?xml version="1.0" ?>
<!-- =================================================================================== -->
<!-- |    This document was autogenerated by xacro from robot.urdf.xacro               | -->
<!-- |    EDITING THIS FILE BY HAND IS NOT RECOMMENDED                                 | -->
<!-- =================================================================================== -->
<robot name="dshape">
  <link name="base_footprint"/>
  <joint name="base_footprint_joint" type="fixed">
    <parent link="base_footprint"/>
    <child link="base_link"/>
    <origin rpy="0 0 0" xyz="0 0 0"/>
  </joint>
  <link name="base_link">
    <inertial>
      <origin rpy="0 0 0" xyz="-0.020088 -9.2937E-05 0.02136"/>
      <mass value="2.4154"/>
      <inertia ixx="0.0062254" ixy="3.3866E-07" ixz="0.00015974" iyy="0.0043358" iyz="-3.09E-06" izz="0.0097947"/>
    </inertial>
    <visual>
      <origin rpy="0 0 0" xyz="0 0 0"/>
      <geometry>
        <mesh filename="package://dshape_description/meshes/base_link.STL"/>
      </geometry>
      <material name="">
        <color rgba="0 0 0 1"/>
      </material>
    </visual>
    <collision>
      <origin rpy="0 0 0" xyz="0 0 0"/>
      <geometry>
        <mesh filename="package://dshape_description/meshes/base_link.STL"/>
      </geometry>
    </collision>
  </link>
  <link name="right_wheel">
    <inertial>
      <origin rpy="0 0 0" xyz="-6.6265E-06 -4.8357E-05 1.088E-05"/>
      <mass value="0.017988"/>
      <inertia ixx="1.232E-05" ixy="-1.1651E-10" ixz="-1.2027E-09" iyy="2.4408E-05" iyz="2.0648E-10" izz="1.2322E-05"/>
    </inertial>
    <visual>
      <origin rpy="0 0 0" xyz="0 0 0"/>
      <geometry>
        <mesh filename="package://dshape_description/meshes/right_wheel.STL"/>
      </geometry>
      <material name="">
        <color rgba="0.29804 0.29804 0.29804 1"/>
      </material>
    </visual>
    <collision>
      <origin rpy="0 0 0" xyz="0 0 0"/>
      <geometry>
        <mesh filename="package://dshape_description/meshes/right_wheel.STL"/>
      </geometry>
      <surface>
        <friction>
          <ode>
            <mu>1</mu>
            <mu2>1</mu2>
            <fdir1>0 0 0</fdir1>
            <slip1>0</slip1>
            <slip2>0</slip2>
          </ode>
        </friction>
      </surface>
    </collision>
  </link>
  <joint name="right_wheel_joint" type="continuous">
    <origin rpy="0 0 0" xyz="-0.037981 -0.11991 -0.011849"/>
    <parent link="base_link"/>
    <child link="right_wheel"/>
    <axis xyz="0 1 0"/>
  </joint>
  <link name="left_wheel">
    <inertial>
      <origin rpy="0 0 0" xyz="6.6265E-06 4.8357E-05 1.088E-05"/>
      <mass value="0.017988"/>
      <inertia ixx="1.232E-05" ixy="-1.1651E-10" ixz="1.2027E-09" iyy="2.4408E-05" iyz="-2.0648E-10" izz="1.2322E-05"/>
    </inertial>
    <visual>
      <origin rpy="0 0 0" xyz="0 0 0"/>
      <geometry>
        <mesh filename="package://dshape_description/meshes/left_wheel.STL"/>
      </geometry>
      <material name="">
        <color rgba="0.29804 0.29804 0.29804 1"/>
      </material>
    </visual>
    <collision>
      <origin rpy="0 0 0" xyz="0 0 0"/>
      <geometry>
        <mesh filename="package://dshape_description/meshes/left_wheel.STL"/>
      </geometry>
      <surface>
        <friction>
          <ode>
            <mu>1</mu>
            <mu2>1</mu2>
            <fdir1>0 0 0</fdir1>
            <slip1>0</slip1>
            <slip2>0</slip2>
          </ode>
        </friction>
      </surface>
    </collision>
  </link>
  <joint name="left_wheel_joint" type="continuous">
    <origin rpy="0 0 0" xyz="-0.03813 0.11892 -0.011747"/>
    <parent link="base_link"/>
    <child link="left_wheel"/>
    <axis xyz="0 1 0"/>
  </joint>
  <!-- lidar -->
  <link name="lidar"/>
  <joint name="lidar_joint" type="fixed">
    <parent link="base_link"/>
    <child link="lidar"/>
    <origin rpy="0 0 0" xyz="0 0 0.02"/>
  </joint>
  <link name="camera"/>
  <joint name="camera_joint" type="fixed">
    <parent link="base_link"/>
    <child link="camera"/>
    <origin rpy="0 0 0" xyz="0 0 0.03"/>
  </joint>
  <!-- Colour -->
  <gazebo reference="base_link">
    <material>Gazebo/Black</material>
  </gazebo>
  <gazebo reference="right_wheel">
    <material>Gazebo/Yellow</material>
    <mu1>1.0</mu1>
    <mu2>1.0</mu2>
  </gazebo>
  <gazebo reference="left_wheel">
    <material>Gazebo/Yellow</material>
    <mu1>1.0</mu1>
    <mu2>1.0</mu2>
  </gazebo>
  <gazebo reference="lidar">
    <material>Gazebo/White</material>
  </gazebo>
  <ros2_control name="DiffBot" type="system">
    <hardware>
      <plugin>stm32f1_system_interface/DiffDriveStm32Hardware</plugin>
      <param name="left_wheel_name">left_wheel_joint</param>
      <param name="right_wheel_name">right_wheel_joint</param>
      <param name="loop_rate">50</param>
      <param name="device">/dev/ttyUSB0</param>
      <!--fixed-->
      <param name="baud_rate">115200</param>
      <param name="timeout_ms">1000</param>
      <param name="enc_counts_per_rev">1320</param>
    </hardware>
    <joint name="left_wheel_joint">
      <command_interface name="velocity">
        <param name="min">-50</param>
        <param name="max">50</param>
      </command_interface>
      <state_interface name="velocity"/>
      <state_interface name="position"/>
    </joint>
    <joint name="right_wheel_joint">
      <command_interface name="velocity">
        <param name="min">-50</param>
        <param name="max">50</param>
      </command_interface>
      <state_interface name="velocity"/>
      <state_interface name="position"/>
    </joint>
  </ros2_control>
</robot>
